Workbook

Sheet Incident_Data
A1: Incident_ID | B1: Date | C1: Incident_Type | D1: Severity | E1: Status | F1: Department | G1: Responsible_Team | H1: Resolution_Time_Days | I1: Cost_Impact_USD | J1: Root_Cause | K1: Control_Domain | L1: Regulatory_Exposure | M1: Escalation_Level | N1: Third_Party_Involved | O1: SLA_Target_Days | P1: SLA_Breached
A2: INC0001 | B2: 45428 | C2: Malware | D2: Medium | E2: Open | F2: Operations | G2: Compliance | H2: 16 | I2: 94101 | J2: Malicious attachment | K2: Endpoint Security | L2: Contractual | M2: CISO / Department Head | N2: No | O2: 14 | P2: Pending
A3: INC0002 | B3: 45432 | C3: Misconfiguration | D3: High | E3: On Hold | F3: Finance | G3: Compliance | H3: 17 | I3: 85119 | J3: Access rule misconfiguration | K3: Configuration Management | L3: None | M3: Executive / CISO | N3: Yes | O3: 7 | P3: Pending
A4: INC0003 | B4: 45653 | C4: Malware | D4: High | E4: Closed | F4: HR | G4: IT Security | H4: 8 | I4: 99720 | J4: Unsafe software installation | K4: Endpoint Security | L4: None | M4: Executive / CISO | N4: No | O4: 7 | P4: Yes
A5: INC0004 | B5: 45405 | C5: Malware | D5: High | E5: Closed | F5: HR | G5: SOC | H5: 13 | I5: 80858 | J5: Malicious attachment | K5: Endpoint Security | L5: None | M5: Executive / CISO | N5: No | O5: 7 | P5: Yes
A6: INC0005 | B6: 45348 | C6: DDoS | D6: High | E6: Closed | F6: Finance | G6: IT Security | H6: 26 | I6: 14076 | J6: Capacity planning gap | K6: Network Resilience | L6: Financial Data | M6: Executive / CISO | N6: No | O6: 7 | P6: Yes
A7: INC0006 | B7: 45321 | C7: DDoS | D7: Low | E7: Closed | F7: Operations | G7: SOC | H7: 27 | I7: 67086 | J7: Insufficient rate limiting | K7: Network Resilience | L7: Operational | M7: Operational | N7: No | O7: 30 | P7: No
A8: INC0007 | B8: 45430 | C8: Phishing | D8: High | E8: Closed | F8: Finance | G8: SOC | H8: 23 | I8: 41743 | J8: Spoofed business email | K8: Security Awareness | L8: Privacy | M8: Executive / CISO | N8: No | O8: 7 | P8: Yes
A9: INC0008 | B9: 45342 | C9: Unauthorized Access | D9: Low | E9: Closed | F9: HR | G9: Compliance | H9: 13 | I9: 64337 | J9: Excessive privileges | K9: Identity & Access Management | L9: Privacy | M9: Operational | N9: No | O9: 30 | P9: No
A10: INC0009 | B10: 45558 | C10: DDoS | D10: Medium | E10: In Progress | F10: HR | G10: Compliance | H10: 10 | I10: 96050 | J10: Insufficient rate limiting | K10: Network Resilience | L10: None | M10: CISO / Department Head | N10: No | O10: 14 | P10: Pending
A11: INC0010 | B11: 45310 | C11: Phishing | D11: High | E11: Open | F11: Finance | G11: Compliance | H11: 12 | I11: 24146 | J11: Credential harvesting | K11: Security Awareness | L11: Financial Data | M11: Executive / CISO | N11: No | O11: 7 | P11: Pending
A12: INC0011 | B12: 45649 | C12: Data Leak | D12: High | E12: Closed | F12: Finance | G12: SOC | H12: 21 | I12: 95926 | J12: Data handling error | K12: Data Protection | L12: Privacy | M12: Executive / CISO | N12: Yes | O12: 7 | P12: Yes
A13: INC0012 | B13: 45300 | C13: Data Leak | D13: Medium | E13: Closed | F13: IT | G13: SOC | H13: 17 | I13: 3268 | J13: Data handling error | K13: Data Protection | L13: None | M13: CISO / Department Head | N13: No | O13: 14 | P13: Yes
... A181: INC0180 | B181: 45819 | C181: Misconfiguration | D181: High | E181: Closed | F181: Operations | G181: DevOps | H181: 10 | I181: 40880 | J181: Change-control failure | K181: Configuration Management | L181: Operational | M181: Executive / CISO | N181: No | O181: 7 | P181: Yes

Sheet Data_Dictionary
A1: Field | B1: Description | C1: Example / Values
A2: Incident_ID | B2: Unique simulated incident identifier. | C2: INC0001
A3: Date | B3: Date on which the incident was recorded. | C3: 2025-03-17
A4: Incident_Type | B4: Primary incident category. | C4: Malware, Phishing, Data Leak, Cloud Exposure, etc.
A5: Severity | B5: Business/security severity assigned to the incident. | C5: Low, Medium, High, Critical
A6: Status | B6: Current incident state. | C6: Closed, In Progress, Open, On Hold
A7: Department | B7: Business unit most directly affected. | C7: Finance, HR, IT, Operations, etc.
A8: Responsible_Team | B8: Team accountable for coordinating the response. | C8: SOC, IT Security, GRC, IAM, Cloud Security, etc.
A9: Resolution_Time_Days | B9: Days taken to resolve a closed incident or elapsed days recorded for an unresolved incident. | C9: 1–30+
A10: Cost_Impact_USD | B10: Estimated direct and indirect cost impact in US dollars. | C10: 25000
A11: Root_Cause | B11: Primary contributing root-cause category. | C11: Compromised credentials, Change-control failure, etc.
A12: Control_Domain | B12: Governance/control domain associated with the incident. | C12: Identity & Access Management, Data Protection, etc.
... A17: SLA_Breached | B17: Whether a closed incident exceeded the simulated resolution SLA; unresolved incidents are Pending. | C17: Yes / No / Pending

Sheet Analysis_Template
A1: GRC102 Week 3 Student Analysis Template
A2: Answer sheet for Part D. Every result below is a live link to the analysis sheets in this workbook.
A3: Analysis Requirement | B3: Result / where to find it
A4: Total number of incidents | B4: ='Core Analysis'!B6 -> 180
A5: Distribution by Incident_Type | B5: ="12 categories; largest: "&'Core Analysis'!A17&" ("&'Core Analysis'!B17&"), "&'Core Analysis'!A18&" ("&'Core Analysis'!B18&"). Full table: Core_Analysis section 1" -> 12 categories; largest: Malware (28), Phishing (28). Full table: Core_Analysis section 1
A6: Average Resolution_Time_Days by Severity | B6: ="Critical "&TEXT('Core Analysis'!C54,"0.00")&" | High "&TEXT('Core Analysis'!C55,"0.00")&" | Medium "&TEXT('Core Analysis'!C56,"0.00")&" | Low "&TEXT('Core Analysis'!C57,"0.00")&" days (Core_Analysis section 4)" -> Critical 9.80 | High 12.72 | Medium 14.74 | Low 18.15 days (Core_Analysis section 4)
A7: Total Cost_Impact_USD by Department | B7: ="Highest: "&'Core Analysis'!A62&" "&TEXT('Core Analysis'!C62,"$#,##0")&". Full table: Core Analysis_Template!C20Analysis section 5" -> Highest: Finance $1,756,282. Full table: Core Analysis_Template!C20Analysis section 5
A8: Total Cost_Impact_USD by Responsible_Team | B8: ="Highest: "&'Core Analysis'!A75&" "&TEXT('Core Analysis'!C75,"$#,##0")&". Full table: Core_Analysis section 6" -> Highest: Compliance $2,836,299. Full table: Core_Analysis section 6
A9: Top 3 Incident_Type categories by average Cost_Impact_USD | B9: ='Core Analysis'!B48&" ("&TEXT('Core Analysis'!C48,"$#,##0")&"); "&'Core Analysis'!B49&" ("&TEXT('Core Analysis'!C49,"$#,##0")&"); "&'Core Analysis'!B50&" ("&TEXT('Core Analysis'!C50,"$#,##0")&")" -> Insider Threat ($138,506); Cloud Exposure ($94,846); Third-Party Breach ($92,888)
A10: Percentage of incidents that are Open or In Progress | B10: =TEXT('Core Analysis'!B10,"0.00%")&" ("&'Core Analysis'!B9&" of "&'Core Analysis'!B6&")" -> 25.56% (46 of 180)
A11: SLA breach pattern by Severity / Responsible_Team (advanced) | B11: See SLA_Analysis (severity, team, and team x severity tables)
A12: Regulatory exposure trends (advanced) | B12: See Regulatory_Exposure (category summary, department matrix, incident-type view)
A13: Third-party involvement trends (advanced) | B13: See Third_Party (cost, resolution, severity, escalation, Welch test)
A14: Most important governance insight #1 | B14: =CISO_Board_Insights!B5 -> Critical and High severity incidents frequently miss their SLA targets.
A15: Governance recommendation #1 | B15: =CISO_Board_Insights!F5 -> Review SLA targets and the escalation process for Critical and High incidents; use a dashboard that automatically escalates cases approaching their SLA limit.
A16: Most important governance insight #2 | B16: =CISO_Board_Insights!B6 -> Insider Threat is infrequent but has the highest average cost.
A17: Governance recommendation #2 | B17: =CISO_Board_Insights!F6 -> Strengthen privileged access reviews, add monitoring of unusual user activity, and connect the HR termination process to IAM so access is removed quickly.
A18: Most important governance insight #3 | B18: =CISO_Board_Insights!B7 -> Identity and Access Management has the most incidents of any control domain.
A19: Governance recommendation #3 | B19: =CISO_Board_Insights!F7 -> Implement or strengthen Privileged Access Management, enforce phishing-resistant MFA for privileged accounts and sensitive help-desk actions, and run quarterly privileged-access reviews.

Sheet Core Analysis
A1: Part D1 - Core Analysis
A2: All numbers are live formulas on Incident_Data. Row labels are typed; every value recalculates from the source rows (original Incident_ID values retained on Incident_Data).
A4: Headline metrics
A5: Metric | B5: Value | C5: Method
A6: Total number of incidents | B6: =COUNTA(Incident_Data!$A$2:$A$181) -> 180 | C6: COUNTA of Incident_ID
A7: Status = Open | B7: =COUNTIF(Incident_Data!$E$2:$E$181,"Open") -> 23 | C7: COUNTIF Status
A8: Status = In Progress | B8: =COUNTIF(Incident_Data!$E$2:$E$181,"In Progress") -> 23 | C8: COUNTIF Status
A9: Open + In Progress | B9: =B7+B8 -> 46 | C9: Sum of the two rows above
A10: % of incidents Open or In Progress | B10: =B9/B6 -> 0.25555556 | C10: Open + In Progress / Total
A11: Total Cost_Impact_USD | B11: =SUM(Incident_Data!$I$2:$I$181) -> 10293422 | C11: SUM Cost_Impact_USD
A12: Average cost per incident | B12: =B11/B6 -> 57185.678 | C12: Total cost / Total incidents
A15: 1. Distribution by Incident_Type (sorted by count)
A16: Incident_Type | B16: Count | C16: % of total
A17: Malware | B17: =COUNTIF(Incident_Data!$C$2:$C$181,A17) -> 28 | C17: =B17/$B$6 -> 0.15555556
A18: Phishing | B18: =COUNTIF(Incident_Data!$C$2:$C$181,A18) -> 28 | C18: =B18/$B$6 -> 0.15555556
A19: Data Leak | B19: =COUNTIF(Incident_Data!$C$2:$C$181,A19) -> 27 | C19: =B19/$B$6 -> 0.15
A20: Unauthorized Access | B20: =COUNTIF(Incident_Data!$C$2:$C$181,A20) -> 24 | C20: =B20/$B$6 -> 0.13333333
A21: Misconfiguration | B21: =COUNTIF(Incident_Data!$C$2:$C$181,A21) -> 19 | C21: =B21/$B$6 -> 0.10555556
A22: DDoS | B22: =COUNTIF(Incident_Data!$C$2:$C$181,A22) -> 19 | C22: =B22/$B$6 -> 0.10555556
A23: Cloud Exposure | B23: =COUNTIF(Incident_Data!$C$2:$C$181,A23) -> 11 | C23: =B23/$B$6 -> 0.061111111
A24: Credential Theft | B24: =COUNTIF(Incident_Data!$C$2:$C$181,A24) -> 9 | C24: =B24/$B$6 -> 0.05
A25: Third-Party Breach | B25: =COUNTIF(Incident_Data!$C$2:$C$181,A25) -> 6 | C25: =B25/$B$6 -> 0.033333333
A26: Insider Threat | B26: =COUNTIF(Incident_Data!$C$2:$C$181,A26) -> 5 | C26: =B26/$B$6 -> 0.027777778
A27: Lost Device | B27: =COUNTIF(Incident_Data!$C$2:$C$181,A27) -> 3 | C27: =B27/$B$6 -> 0.016666667
A28: Policy Violation | B28: =COUNTIF(Incident_Data!$C$2:$C$181,A28) -> 1 | C28: =B28/$B$6 -> 0.0055555556
A29: Total | B29: =SUM(B17:B28) -> 180 | C29: =SUM(C17:C28) -> 1
A31: 2. Average Cost_Impact_USD by Incident_Type (sorted highest first)
A32: Incident_Type | B32: Incidents | C32: Average cost (USD) | D32: Total cost (USD) | E32: Rank (1 = highest avg)
A33: Insider Threat | B33: =COUNTIF(Incident_Data!$C$2:$C$181,A33) -> 5 | C33: =AVERAGEIF(Incident_Data!$C$2:$C$181,A33,Incident_Data!$I$2:$I$181) -> 138506 | D33: =SUMIF(Incident_Data!$C$2:$C$181,A33,Incident_Data!$I$2:$I$181) -> 692530 | E33: =RANK(C33,$C$33:$C$44) -> 1
A34: Cloud Exposure | B34: =COUNTIF(Incident_Data!$C$2:$C$181,A34) -> 11 | C34: =AVERAGEIF(Incident_Data!$C$2:$C$181,A34,Incident_Data!$I$2:$I$181) -> 94846.364 | D34: =SUMIF(Incident_Data!$C$2:$C$181,A34,Incident_Data!$I$2:$I$181) -> 1043310 | E34: =RANK(C34,$C$33:$C$44) -> 2
A35: Third-Party Breach | B35: =COUNTIF(Incident_Data!$C$2:$C$181,A35) -> 6 | C35: =AVERAGEIF(Incident_Data!$C$2:$C$181,A35,Incident_Data!$I$2:$I$181) -> 92888.333 | D35: =SUMIF(Incident_Data!$C$2:$C$181,A35,Incident_Data!$I$2:$I$181) -> 557330 | E35: =RANK(C35,$C$33:$C$44) -> 3
A36: Unauthorized Access | B36: =COUNTIF(Incident_Data!$C$2:$C$181,A36) -> 24 | C36: =AVERAGEIF(Incident_Data!$C$2:$C$181,A36,Incident_Data!$I$2:$I$181) -> 59281.208 | D36: =SUMIF(Incident_Data!$C$2:$C$181,A36,Incident_Data!$I$2:$I$181) -> 1422749 | E36: =RANK(C36,$C$33:$C$44) -> 4
A37: Credential Theft | B37: =COUNTIF(Incident_Data!$C$2:$C$181,A37) -> 9 | C37: =AVERAGEIF(Incident_Data!$C$2:$C$181,A37,Incident_Data!$I$2:$I$181) -> 56635.556 | D37: =SUMIF(Incident_Data!$C$2:$C$181,A37,Incident_Data!$I$2:$I$181) -> 509720 | E37: =RANK(C37,$C$33:$C$44) -> 5
A38: DDoS | B38: =COUNTIF(Incident_Data!$C$2:$C$181,A38) -> 19 | C38: =AVERAGEIF(Incident_Data!$C$2:$C$181,A38,Incident_Data!$I$2:$I$181) -> 55859.421 | D38: =SUMIF(Incident_Data!$C$2:$C$181,A38,Incident_Data!$I$2:$I$181) -> 1061329 | E38: =RANK(C38,$C$33:$C$44) -> 6
A39: Malware | B39: =COUNTIF(Incident_Data!$C$2:$C$181,A39) -> 28 | C39: =AVERAGEIF(Incident_Data!$C$2:$C$181,A39,Incident_Data!$I$2:$I$181) -> 54576.179 | D39: =SUMIF(Incident_Data!$C$2:$C$181,A39,Incident_Data!$I$2:$I$181) -> 1528133 | E39: =RANK(C39,$C$33:$C$44) -> 7
A40: Data Leak | B40: =COUNTIF(Incident_Data!$C$2:$C$181,A40) -> 27 | C40: =AVERAGEIF(Incident_Data!$C$2:$C$181,A40,Incident_Data!$I$2:$I$181) -> 53801.37 | D40: =SUMIF(Incident_Data!$C$2:$C$181,A40,Incident_Data!$I$2:$I$181) -> 1452637 | E40: =RANK(C40,$C$33:$C$44) -> 8
A41: Misconfiguration | B41: =COUNTIF(Incident_Data!$C$2:$C$181,A41) -> 19 | C41: =AVERAGEIF(Incident_Data!$C$2:$C$181,A41,Incident_Data!$I$2:$I$181) -> 46318.053 | D41: =SUMIF(Incident_Data!$C$2:$C$181,A41,Incident_Data!$I$2:$I$181) -> 880043 | E41: =RANK(C41,$C$33:$C$44) -> 9
A42: Phishing | B42: =COUNTIF(Incident_Data!$C$2:$C$181,A42) -> 28 | C42: =AVERAGEIF(Incident_Data!$C$2:$C$181,A42,Incident_Data!$I$2:$I$181) -> 38061.821 | D42: =SUMIF(Incident_Data!$C$2:$C$181,A42,Incident_Data!$I$2:$I$181) -> 1065731 | E42: =RANK(C42,$C$33:$C$44) -> 10
A43: Lost Device | B43: =COUNTIF(Incident_Data!$C$2:$C$181,A43) -> 3 | C43: =AVERAGEIF(Incident_Data!$C$2:$C$181,A43,Incident_Data!$I$2:$I$181) -> 20836.667 | D43: =SUMIF(Incident_Data!$C$2:$C$181,A43,Incident_Data!$I$2:$I$181) -> 62510 | E43: =RANK(C43,$C$33:$C$44) -> 11
A44: Policy Violation | B44: =COUNTIF(Incident_Data!$C$2:$C$181,A44) -> 1 | C44: =AVERAGEIF(Incident_Data!$C$2:$C$181,A44,Incident_Data!$I$2:$I$181) -> 17400 | D44: =SUMIF(Incident_Data!$C$2:$C$181,A44,Incident_Data!$I$2:$I$181) -> 17400 | E44: =RANK(C44,$C$33:$C$44) -> 12
...

Sheet SLA_Analysis
A1: Part D2 - SLA_Breached patterns
A2: SLA_Breached = Yes/No only exists for Closed incidents; unresolved incidents are Pending (Data_Dictionary). 'Past target' compares elapsed days with SLA_Target_Days.
A4: 1. SLA outcome by Severity
A5: Severity | B5: No | C5: Pending | D5: Yes (breached) | E5: Total | F5: Breach rate (all incidents) | G5: Breach rate (Closed only) | H5: Pending already past SLA target | I5: Breached + pending past target, % of total
A6: Critical | B6: =COUNTIFS(Incident_Data!$D$2:$D$181,$A6,Incident_Data!$P$2:$P$181,"No") -> 5 | C6: =COUNTIFS(Incident_Data!$D$2:$D$181,$A6,Incident_Data!$P$2:$P$181,"Pending") -> 3 | D6: =COUNTIFS(Incident_Data!$D$2:$D$181,$A6,Incident_Data!$P$2:$P$181,"Yes") -> 12 | E6: =SUM(B6:D6) -> 20 | F6: =D6/E6 -> 0.6 | G6: =IF(B6+D6=0,0,D6/(B6+D6)) -> 0.70588235 | H6: =SUMPRODUCT((Incident_Data!$D$2:$D$181=$A6)*(Incident_Data!$P$2:$P$181="Pending")*(Incident_Data!$H$2:$H$181>Incident_Data!$O$2:$O$181)) -> 2 | I6: =(D6+H6)/E6 -> 0.7
A7: High | B7: =COUNTIFS(Incident_Data!$D$2:$D$181,$A7,Incident_Data!$P$2:$P$181,"No") -> 9 | C7: =COUNTIFS(Incident_Data!$D$2:$D$181,$A7,Incident_Data!$P$2:$P$181,"Pending") -> 19 | D7: =COUNTIFS(Incident_Data!$D$2:$D$181,$A7,Incident_Data!$P$2:$P$181,"Yes") -> 25 | E7: =SUM(B7:D7) -> 53 | F7: =D7/E7 -> 0.47169811 | G7: =IF(B7+D7=0,0,D7/(B7+D7)) -> 0.73529412 | H7: =SUMPRODUCT((Incident_Data!$D$2:$D$181=$A7)*(Incident_Data!$P$2:$P$181="Pending")*(Incident_Data!$H$2:$H$181>Incident_Data!$O$2:$O$181)) -> 17 | I7: =(D7+H7)/E7 -> 0.79245283
A8: Medium | B8: =COUNTIFS(Incident_Data!$D$2:$D$181,$A8,Incident_Data!$P$2:$P$181,"No") -> 32 | C8: =COUNTIFS(Incident_Data!$D$2:$D$181,$A8,Incident_Data!$P$2:$P$181,"Pending") -> 31 | D8: =COUNTIFS(Incident_Data!$D$2:$D$181,$A8,Incident_Data!$P$2:$P$181,"Yes") -> 17 | E8: =SUM(B8:D8) -> 80 | F8: =D8/E8 -> 0.2125 | G8: =IF(B8+D8=0,0,D8/(B8+D8)) -> 0.34693878 | H8: =SUMPRODUCT((Incident_Data!$D$2:$D$181=$A8)*(Incident_Data!$P$2:$P$181="Pending")*(Incident_Data!$H$2:$H$181>Incident_Data!$O$2:$O$181)) -> 22 | I8: =(D8+H8)/E8 -> 0.4875
A9: Low | B9: =COUNTIFS(Incident_Data!$D$2:$D$181,$A9,Incident_Data!$P$2:$P$181,"No") -> 17 | C9: =COUNTIFS(Incident_Data!$D$2:$D$181,$A9,Incident_Data!$P$2:$P$181,"Pending") -> 10 | D9: =COUNTIFS(Incident_Data!$D$2:$D$181,$A9,Incident_Data!$P$2:$P$181,"Yes") -> 0 | E9: =SUM(B9:D9) -> 27 | F9: =D9/E9 -> 0 | G9: =IF(B9+D9=0,0,D9/(B9+D9)) -> 0 | H9: =SUMPRODUCT((Incident_Data!$D$2:$D$181=$A9)*(Incident_Data!$P$2:$P$181="Pending")*(Incident_Data!$H$2:$H$181>Incident_Data!$O$2:$O$181)) -> 2 | I9: =(D9+H9)/E9 -> 0.074074074
A10: All | B10: =SUM(B6:B9) -> 63 | C10: =SUM(C6:C9) -> 63 | D10: =SUM(D6:D9) -> 54 | E10: =SUM(E6:E9) -> 180 | F10: =D10/E10 -> 0.3 | G10: =D10/(B10+D10) -> 0.46153846 | H10: =SUM(H6:H9) -> 43 | I10: =(D10+H10)/E10 -> 0.53888889
A12: 2. SLA outcome by Responsible_Team (all eight teams)
A13: Responsible_Team | B13: No | C13: Pending | D13: Yes (breached) | E13: Total | F13: Breach rate (all incidents) | G13: Breach rate (Closed only) | H13: Pending already past SLA target | I13: Total cost (USD)
A14: Compliance | B14: =COUNTIFS(Incident_Data!$G$2:$G$181,$A14,Incident_Data!$P$2:$P$181,"No") -> 14 | C14: =COUNTIFS(Incident_Data!$G$2:$G$181,$A14,Incident_Data!$P$2:$P$181,"Pending") -> 20 | D14: =COUNTIFS(Incident_Data!$G$2:$G$181,$A14,Incident_Data!$P$2:$P$181,"Yes") -> 8 | E14: =SUM(B14:D14) -> 42 | F14: =D14/E14 -> 0.19047619 | G14: =IF(B14+D14=0,0,D14/(B14+D14)) -> 0.36363636 | H14: =SUMPRODUCT((Incident_Data!$G$2:$G$181=$A14)*(Incident_Data!$P$2:$P$181="Pending")*(Incident_Data!$H$2:$H$181>Incident_Data!$O$2:$O$181)) -> 14 | I14: =SUMIF(Incident_Data!$G$2:$G$181,$A14,Incident_Data!$I$2:$I$181) -> 2836299
A15: IT Security | B15: =COUNTIFS(Incident_Data!$G$2:$G$181,$A15,Incident_Data!$P$2:$P$181,"No") -> 9 | C15: =COUNTIFS(Incident_Data!$G$2:$G$181,$A15,Incident_Data!$P$2:$P$181,"Pending") -> 14 | D15: =COUNTIFS(Incident_Data!$G$2:$G$181,$A15,Incident_Data!$P$2:$P$181,"Yes") -> 15 | E15: =SUM(B15:D15) -> 38 | F15: =D15/E15 -> 0.39473684 | G15: =IF(B15+D15=0,0,D15/(B15+D15)) -> 0.625 | H15: =SUMPRODUCT((Incident_Data!$G$2:$G$181=$A15)*(Incident_Data!$P$2:$P$181="Pending")*(Incident_Data!$H$2:$H$181>Incident_Data!$O$2:$O$181)) -> 8 | I15: =SUMIF(Incident_Data!$G$2:$G$181,$A15,Incident_Data!$I$2:$I$181) -> 1763143
A16: SOC | B16: =COUNTIFS(Incident_Data!$G$2:$G$181,$A16,Incident_Data!$P$2:$P$181,"No") -> 13 | C16: =COUNTIFS(Incident_Data!$G$2:$G$181,$A16,Incident_Data!$P$2:$P$181,"Pending") -> 12 | D16: =COUNTIFS(Incident_Data!$G$2:$G$181,$A16,Incident_Data!$P$2:$P$181,"Yes") -> 11 | E16: =SUM(B16:D16) -> 36 | F16: =D16/E16 -> 0.30555556 | G16: =IF(B16+D16=0,0,D16/(B16+D16)) -> 0.45833333 | H16: =SUMPRODUCT((Incident_Data!$G$2:$G$181=$A16)*(Incident_Data!$P$2:$P$181="Pending")*(Incident_Data!$H$2:$H$181>Incident_Data!$O$2:$O$181)) -> 7 | I16: =SUMIF(Incident_Data!$G$2:$G$181,$A16,Incident_Data!$I$2:$I$181) -> 1624054
A17: DevOps | B17: =COUNTIFS(Incident_Data!$G$2:$G$181,$A17,Incident_Data!$P$2:$P$181,"No") -> 12 | C17: =COUNTIFS(Incident_Data!$G$2:$G$181,$A17,Incident_Data!$P$2:$P$181,"Pending") -> 8 | D17: =COUNTIFS(Incident_Data!$G$2:$G$181,$A17,Incident_Data!$P$2:$P$181,"Yes") -> 13 | E17: =SUM(B17:D17) -> 33 | F17: =D17/E17 -> 0.39393939 | G17: =IF(B17+D17=0,0,D17/(B17+D17)) -> 0.52 | H17: =SUMPRODUCT((Incident_Data!$G$2:$G$181=$A17)*(Incident_Data!$P$2:$P$181="Pending")*(Incident_Data!$H$2:$H$181>Incident_Data!$O$2:$O$181)) -> 6 | I17: =SUMIF(Incident_Data!$G$2:$G$181,$A17,Incident_Data!$I$2:$I$181) -> 2079986
A18: Incident Response | B18: =COUNTIFS(Incident_Data!$G$2:$G$181,$A18,Incident_Data!$P$2:$P$181,"No") -> 9 | C18: =COUNTIFS(Incident_Data!$G$2:$G$181,$A18,Incident_Data!$P$2:$P$181,"Pending") -> 4 | D18: =COUNTIFS(Incident_Data!$G$2:$G$181,$A18,Incident_Data!$P$2:$P$181,"Yes") -> 1 | E18: =SUM(B18:D18) -> 14 | F18: =D18/E18 -> 0.071428571 | G18: =IF(B18+D18=0,0,D18/(B18+D18)) -> 0.1 | H18: =SUMPRODUCT((Incident_Data!$G$2:$G$181=$A18)*(Incident_Data!$P$2:$P$181="Pending")*(Incident_Data!$H$2:$H$181>Incident_Data!$O$2:$O$181)) -> 4 | I18: =SUMIF(Incident_Data!$G$2:$G$181,$A18,Incident_Data!$I$2:$I$181) -> 646370
A19: GRC | B19: =COUNTIFS(Incident_Data!$G$2:$G$181,$A19,Incident_Data!$P$2:$P$181,"No") -> 5 | C19: =COUNTIFS(Incident_Data!$G$2:$G$181,$A19,Incident_Data!$P$2:$P$181,"Pending") -> 2 | D19: =COUNTIFS(Incident_Data!$G$2:$G$181,$A19,Incident_Data!$P$2:$P$181,"Yes") -> 4 | E19: =SUM(B19:D19) -> 11 | F19: =D19/E19 -> 0.36363636 | G19: =IF(B19+D19=0,0,D19/(B19+D19)) -> 0.44444444 | H19: =SUMPRODUCT((Incident_Data!$G$2:$G$181=$A19)*(Incident_Data!$P$2:$P$181="Pending")*(Incident_Data!$H$2:$H$181>Incident_Data!$O$2:$O$181)) -> 2 | I19: =SUMIF(Incident_Data!$G$2:$G$181,$A19,Incident_Data!$I$2:$I$181) -> 964680
A20: IAM | B20: =COUNTIFS(Incident_Data!$G$2:$G$181,$A20,Incident_Data!$P$2:$P$181,"No") -> 0 | C20: =COUNTIFS(Incident_Data!$G$2:$G$181,$A20,Incident_Data!$P$2:$P$181,"Pending") -> 2 | D20: =COUNTIFS(Incident_Data!$G$2:$G$181,$A20,Incident_Data!$P$2:$P$181,"Yes") -> 1 | E20: =SUM(B20:D20) -> 3 | F20: =D20/E20 -> 0.33333333 | G20: =IF(B20+D20=0,0,D20/(B20+D20)) -> 1 | H20: =SUMPRODUCT((Incident_Data!$G$2:$G$181=$A20)*(Incident_Data!$P$2:$P$181="Pending")*(Incident_Data!$H$2:$H$181>Incident_Data!$O$2:$O$181)) -> 1 | I20: =SUMIF(Incident_Data!$G$2:$G$181,$A20,Incident_Data!$I$2:$I$181) -> 283670
A21: Cloud Security | B21: =COUNTIFS(Incident_Data!$G$2:$G$181,$A21,Incident_Data!$P$2:$P$181,"No") -> 1 | C21: =COUNTIFS(Incident_Data!$G$2:$G$181,$A21,Incident_Data!$P$2:$P$181,"Pending") -> 1 | D21: =COUNTIFS(Incident_Data!$G$2:$G$181,$A21,Incident_Data!$P$2:$P$181,"Yes") -> 1 | E21: =SUM(B21:D21) -> 3 | F21: =D21/E21 -> 0.33333333 | G21: =IF(B21+D21=0,0,D21/(B21+D21)) -> 0.5 | H21: =SUMPRODUCT((Incident_Data!$G$2:$G$181=$A21)*(Incident_Data!$P$2:$P$181="Pending")*(Incident_Data!$H$2:$H$181>Incident_Data!$O$2:$O$181)) -> 1 | I21: =SUMIF(Incident_Data!$G$2:$G$181,$A21,Incident_Data!$I$2:$I$181) -> 95220
A22: All | B22: =SUM(B14:B21) -> 63 | C22: =SUM(C14:C21) -> 63 | D22: =SUM(D14:D21) -> 54 | E22: =SUM(E14:E21) -> 180 | F22: =D22/E22 -> 0.3 | G22: =D22/(B22+D22) -> 0.46153846 | H22: =SUM(H14:H21) -> 43 | I22: =SUM(I14:I21) -> 10293422
A24: 3. Breached incidents (Yes) - Responsible_Team x Severity
A25: Responsible_Team | B25: Critical | C25: High | D25: Medium | E25: Low | F25: Total
A26: Compliance | B26: =COUNTIFS(Incident_Data!$G$2:$G$181,$A26,Incident_Data!$D$2:$D$181,B$25,Incident_Data!$P$2:$P$181,"Yes") -> 1 | C26: =COUNTIFS(Incident_Data!$G$2:$G$181,$A26,Incident_Data!$D$2:$D$181,C$25,Incident_Data!$P$2:$P$181,"Yes") -> 2 | D26: =COUNTIFS(Incident_Data!$G$2:$G$181,$A26,Incident_Data!$D$2:$D$181,D$25,Incident_Data!$P$2:$P$181,"Yes") -> 5 | E26: =COUNTIFS(Incident_Data!$G$2:$G$181,$A26,Incident_Data!$D$2:$D$181,E$25,Incident_Data!$P$2:$P$181,"Yes") -> 0 | F26: =SUM(B26:E26) -> 8
A27: IT Security | B27: =COUNTIFS(Incident_Data!$G$2:$G$181,$A27,Incident_Data!$D$2:$D$181,B$25,Incident_Data!$P$2:$P$181,"Yes") -> 4 | C27: =COUNTIFS(Incident_Data!$G$2:$G$181,$A27,Incident_Data!$D$2:$D$181,C$25,Incident_Data!$P$2:$P$181,"Yes") -> 7 | D27: =COUNTIFS(Incident_Data!$G$2:$G$181,$A27,Incident_Data!$D$2:$D$181,D$25,Incident_Data!$P$2:$P$181,"Yes") -> 4 | E27: =COUNTIFS(Incident_Data!$G$2:$G$181,$A27,Incident_Data!$D$2:$D$181,E$25,Incident_Data!$P$2:$P$181,"Yes") -> 0 | F27: =SUM(B27:E27) -> 15
A28: SOC | B28: =COUNTIFS(Incident_Data!$G$2:$G$181,$A28,Incident_Data!$D$2:$D$181,B$25,Incident_Data!$P$2:$P$181,"Yes") -> 1 | C28: =COUNTIFS(Incident_Data!$G$2:$G$181,$A28,Incident_Data!$D$2:$D$181,C$25,Incident_Data!$P$2:$P$181,"Yes") -> 5 | D28: =COUNTIFS(Incident_Data!$G$2:$G$181,$A28,Incident_Data!$D$2:$D$181,D$25,Incident_Data!$P$2:$P$181,"Yes") -> 5 | E28: =COUNTIFS(Incident_Data!$G$2:$G$181,$A28,Incident_Data!$D$2:$D$181,E$25,Incident_Data!$P$2:$P$181,"Yes") -> 0 | F28: =SUM(B28:E28) -> 11
A29: DevOps | B29: =COUNTIFS(Incident_Data!$G$2:$G$181,$A29,Incident_Data!$D$2:$D$181,B$25,Incident_Data!$P$2:$P$181,"Yes") -> 6 | C29: =COUNTIFS(Incident_Data!$G$2:$G$181,$A29,Incident_Data!$D$2:$D$181,C$25,Incident_Data!$P$2:$P$181,"Yes") -> 4 | D29: =COUNTIFS(Incident_Data!$G$2:$G$181,$A29,Incident_Data!$D$2:$D$181,D$25,Incident_Data!$P$2:$P$181,"Yes") -> 3 | E29: =COUNTIFS(Incident_Data!$G$2:$G$181,$A29,Incident_Data!$D$2:$D$181,E$25,Incident_Data!$P$2:$P$181,"Yes") -> 0 | F29: =SUM(B29:E29) -> 13
A30: Incident Response | B30: =COUNTIFS(Incident_Data!$G$2:$G$181,$A30,Incident_Data!$D$2:$D$181,B$25,Incident_Data!$P$2:$P$181,"Yes") -> 0 | C30: =COUNTIFS(Incident_Data!$G$2:$G$181,$A30,Incident_Data!$D$2:$D$181,C$25,Incident_Data!$P$2:$P$181,"Yes") -> 1 | D30: =COUNTIFS(Incident_Data!$G$2:$G$181,$A30,Incident_Data!$D$2:$D$181,D$25,Incident_Data!$P$2:$P$181,"Yes") -> 0 | E30: =COUNTIFS(Incident_Data!$G$2:$G$181,$A30,Incident_Data!$D$2:$D$181,E$25,Incident_Data!$P$2:$P$181,"Yes") -> 0 | F30: =SUM(B30:E30) -> 1
A31: GRC | B31: =COUNTIFS(Incident_Data!$G$2:$G$181,$A31,Incident_Data!$D$2:$D$181,B$25,Incident_Data!$P$2:$P$181,"Yes") -> 0 | C31: =COUNTIFS(Incident_Data!$G$2:$G$181,$A31,Incident_Data!$D$2:$D$181,C$25,Incident_Data!$P$2:$P$181,"Yes") -> 4 | D31: =COUNTIFS(Incident_Data!$G$2:$G$181,$A31,Incident_Data!$D$2:$D$181,D$25,Incident_Data!$P$2:$P$181,"Yes") -> 0 | E31: =COUNTIFS(Incident_Data!$G$2:$G$181,$A31,Incident_Data!$D$2:$D$181,E$25,Incident_Data!$P$2:$P$181,"Yes") -> 0 | F31: =SUM(B31:E31) -> 4
A32: IAM | B32: =COUNTIFS(Incident_Data!$G$2:$G$181,$A32,Incident_Data!$D$2:$D$181,B$25,Incident_Data!$P$2:$P$181,"Yes") -> 0 | C32: =COUNTIFS(Incident_Data!$G$2:$G$181,$A32,Incident_Data!$D$2:$D$181,C$25,Incident_Data!$P$2:$P$181,"Yes") -> 1 | D32: =COUNTIFS(Incident_Data!$G$2:$G$181,$A32,Incident_Data!$D$2:$D$181,D$25,Incident_Data!$P$2:$P$181,"Yes") -> 0 | E32: =COUNTIFS(Incident_Data!$G$2:$G$181,$A32,Incident_Data!$D$2:$D$181,E$25,Incident_Data!$P$2:$P$181,"Yes") -> 0 | F32: =SUM(B32:E32) -> 1
A33: Cloud Security | B33: =COUNTIFS(Incident_Data!$G$2:$G$181,$A33,Incident_Data!$D$2:$D$181,B$25,Incident_Data!$P$2:$P$181,"Yes") -> 0 | C33: =COUNTIFS(Incident_Data!$G$2:$G$181,$A33,Incident_Data!$D$2:$D$181,C$25,Incident_Data!$P$2:$P$181,"Yes") -> 1 | D33: =COUNTIFS(Incident_Data!$G$2:$G$181,$A33,Incident_Data!$D$2:$D$181,D$25,Incident_Data!$P$2:$P$181,"Yes") -> 0 | E33: =COUNTIFS(Incident_Data!$G$2:$G$181,$A33,Incident_Data!$D$2:$D$181,E$25,Incident_Data!$P$2:$P$181,"Yes") -> 0 | F33: =SUM(B33:E33) -> 1
A34: All | B34: =SUM(B26:B33) -> 12 | C34: =SUM(C26:C33) -> 25 | D34: =SUM(D26:D33) -> 17 | E34: =SUM(E26:E33) -> 0 | F34: =SUM(F26:F33) -> 54

Sheet Regulatory_Exposure
A1: Part D2 - Regulatory_Exposure patterns
A2: 'None' is the recorded value for incidents with no regulatory exposure.
A4: 1. Exposure category summary
A5: Regulatory_Exposure | B5: Incidents | C5: % of total | D5: Total cost (USD) | E5: Average cost (USD)
A6: Privacy | B6: =COUNTIF(Incident_Data!$L$2:$L$181,A6) -> 56 | C6: =B6/'Core Analysis'!$B$6 -> 0.31111111 | D6: =SUMIF(Incident_Data!$L$2:$L$181,A6,Incident_Data!$I$2:$I$181) -> 3208575 | E6: =AVERAGEIF(Incident_Data!$L$2:$L$181,A6,Incident_Data!$I$2:$I$181) -> 57295.982
A7: None | B7: =COUNTIF(Incident_Data!$L$2:$L$181,A7) -> 44 | C7: =B7/'Core Analysis'!$B$6 -> 0.24444444 | D7: =SUMIF(Incident_Data!$L$2:$L$181,A7,Incident_Data!$I$2:$I$181) -> 2658508 | E7: =AVERAGEIF(Incident_Data!$L$2:$L$181,A7,Incident_Data!$I$2:$I$181) -> 60420.636
A8: Contractual | B8: =COUNTIF(Incident_Data!$L$2:$L$181,A8) -> 33 | C8: =B8/'Core Analysis'!$B$6 -> 0.18333333 | D8: =SUMIF(Incident_Data!$L$2:$L$181,A8,Incident_Data!$I$2:$I$181) -> 1923926 | E8: =AVERAGEIF(Incident_Data!$L$2:$L$181,A8,Incident_Data!$I$2:$I$181) -> 58300.788
A9: Financial Data | B9: =COUNTIF(Incident_Data!$L$2:$L$181,A9) -> 14 | C9: =B9/'Core Analysis'!$B$6 -> 0.077777778 | D9: =SUMIF(Incident_Data!$L$2:$L$181,A9,Incident_Data!$I$2:$I$181) -> 788459 | E9: =AVERAGEIF(Incident_Data!$L$2:$L$181,A9,Incident_Data!$I$2:$I$181) -> 56318.5
A10: Operational | B10: =COUNTIF(Incident_Data!$L$2:$L$181,A10) -> 12 | C10: =B10/'Core Analysis'!$B$6 -> 0.066666667 | D10: =SUMIF(Incident_Data!$L$2:$L$181,A10,Incident_Data!$I$2:$I$181) -> 608797 | E10: =AVERAGEIF(Incident_Data!$L$2:$L$181,A10,Incident_Data!$I$2:$I$181) -> 50733.083
A11: Regulatory | B11: =COUNTIF(Incident_Data!$L$2:$L$181,A11) -> 10 | C11: =B11/'Core Analysis'!$B$6 -> 0.055555556 | D11: =SUMIF(Incident_Data!$L$2:$L$181,A11,Incident_Data!$I$2:$I$181) -> 540151 | E11: =AVERAGEIF(Incident_Data!$L$2:$L$181,A11,Incident_Data!$I$2:$I$181) -> 54015.1
A12: Education Records | B12: =COUNTIF(Incident_Data!$L$2:$L$181,A12) -> 6 | C12: =B12/'Core Analysis'!$B$6 -> 0.033333333 | D12: =SUMIF(Incident_Data!$L$2:$L$181,A12,Incident_Data!$I$2:$I$181) -> 473840 | E12: =AVERAGEIF(Incident_Data!$L$2:$L$181,A12,Incident_Data!$I$2:$I$181) -> 78973.333
A13: Employment Data | B13: =COUNTIF(Incident_Data!$L$2:$L$181,A13) -> 4 | C13: =B13/'Core Analysis'!$B$6 -> 0.022222222 | D13: =SUMIF(Incident_Data!$L$2:$L$181,A13,Incident_Data!$I$2:$I$181) -> 75446 | E13: =AVERAGEIF(Incident_Data!$L$2:$L$181,A13,Incident_Data!$I$2:$I$181) -> 18861.5
A14: Research Data | B14: =COUNTIF(Incident_Data!$L$2:$L$181,A14) -> 1 | C14: =B14/'Core Analysis'!$B$6 -> 0.0055555556 | D14: =SUMIF(Incident_Data!$L$2:$L$181,A14,Incident_Data!$I$2:$I$181) -> 15720 | E14: =AVERAGEIF(Incident_Data!$L$2:$L$181,A14,Incident_Data!$I$2:$I$181) -> 15720
A15: Total | B15: =SUM(B6:B14) -> 180 | C15: =SUM(C6:C14) -> 1 | D15: =SUM(D6:D14) -> 10293422 | E15: =D15/B15 -> 57185.678
A17: 2. Department x Regulatory_Exposure (incident counts)
A18: Department | B18: Privacy | C18: None | D18: Contractual | E18: Financial Data | F18: Operational | G18: Regulatory | H18: Education Records | I18: Employment Data | J18: Research Data | K18: Total
A19: Finance | B19: =COUNTIFS(Incident_Data!$F$2:$F$181,$A19,Incident_Data!$L$2:$L$181,B$18) -> 9 | C19: =COUNTIFS(Incident_Data!$F$2:$F$181,$A19,Incident_Data!$L$2:$L$181,C$18) -> 10 | D19: =COUNTIFS(Incident_Data!$F$2:$F$181,$A19,Incident_Data!$L$2:$L$181,D$18) -> 0 | E19: =COUNTIFS(Incident_Data!$F$2:$F$181,$A19,Incident_Data!$L$2:$L$181,E$18) -> 14 | F19: =COUNTIFS(Incident_Data!$F$2:$F$181,$A19,Incident_Data!$L$2:$L$181,F$18) -> 0 | G19: =COUNTIFS(Incident_Data!$F$2:$F$181,$A19,Incident_Data!$L$2:$L$181,G$18) -> 0 | H19: =COUNTIFS(Incident_Data!$F$2:$F$181,$A19,Incident_Data!$L$2:$L$181,H$18) -> 0 | I19: =COUNTIFS(Incident_Data!$F$2:$F$181,$A19,Incident_Data!$L$2:$L$181,I$18) -> 0 | J19: =COUNTIFS(Incident_Data!$F$2:$F$181,$A19,Incident_Data!$L$2:$L$181,J$18) -> 0 | K19: =SUM(B19:J19) -> 33
A20: IT | B20: =COUNTIFS(Incident_Data!$F$2:$F$181,$A20,Incident_Data!$L$2:$L$181,B$18) -> 14 | C20: =COUNTIFS(Incident_Data!$F$2:$F$181,$A20,Incident_Data!$L$2:$L$181,C$18) -> 8 | D20: =COUNTIFS(Incident_Data!$F$2:$F$181,$A20,Incident_Data!$L$2:$L$181,D$18) -> 8 | E20: =COUNTIFS(Incident_Data!$F$2:$F$181,$A20,Incident_Data!$L$2:$L$181,E$18) -> 0 | F20: =COUNTIFS(Incident_Data!$F$2:$F$181,$A20,Incident_Data!$L$2:$L$181,F$18) -> 0 | G20: =COUNTIFS(Incident_Data!$F$2:$F$181,$A20,Incident_Data!$L$2:$L$181,G$18) -> 0 | H20: =COUNTIFS(Incident_Data!$F$2:$F$181,$A20,Incident_Data!$L$2:$L$181,H$18) -> 0 | I20: =COUNTIFS(Incident_Data!$F$2:$F$181,$A20,Incident_Data!$L$2:$L$181,I$18) -> 0 | J20: =COUNTIFS(Incident_Data!$F$2:$F$181,$A20,Incident_Data!$L$2:$L$181,J$18) -> 0 | K20: =SUM(B20:J20) -> 30
A21: Operations | B21: =COUNTIFS(Incident_Data!$F$2:$F$181,$A21,Incident_Data!$L$2:$L$181,B$18) -> 0 | C21: =COUNTIFS(Incident_Data!$F$2:$F$181,$A21,Incident_Data!$L$2:$L$181,C$18) -> 10 | D21: =COUNTIFS(Incident_Data!$F$2:$F$181,$A21,Incident_Data!$L$2:$L$181,D$18) -> 13 | E21: =COUNTIFS(Incident_Data!$F$2:$F$181,$A21,Incident_Data!$L$2:$L$181,E$18) -> 0 | F21: =COUNTIFS(Incident_Data!$F$2:$F$181,$A21,Incident_Data!$L$2:$L$181,F$18) -> 9 | G21: =COUNTIFS(Incident_Data!$F$2:$F$181,$A21,Incident_Data!$L$2:$L$181,G$18) -> 0 | H21: =COUNTIFS(Incident_Data!$F$2:$F$181,$A21,Incident_Data!$L$2:$L$181,H$18) -> 0 | I21: =COUNTIFS(Incident_Data!$F$2:$F$181,$A21,Incident_Data!$L$2:$L$181,I$18) -> 0 | J21: =COUNTIFS(Incident_Data!$F$2:$F$181,$A21,Incident_Data!$L$2:$L$181,J$18) -> 0 | K21: =SUM(B21:J21) -> 32
A22: HR | B22: =COUNTIFS(Incident_Data!$F$2:$F$181,$A22,Incident_Data!$L$2:$L$181,B$18) -> 9 | C22: =COUNTIFS(Incident_Data!$F$2:$F$181,$A22,Incident_Data!$L$2:$L$181,C$18) -> 12 | D22: =COUNTIFS(Incident_Data!$F$2:$F$181,$A22,Incident_Data!$L$2:$L$181,D$18) -> 0 | E22: =COUNTIFS(Incident_Data!$F$2:$F$181,$A22,Incident_Data!$L$2:$L$181,E$18) -> 0 | F22: =COUNTIFS(Incident_Data!$F$2:$F$181,$A22,Incident_Data!$L$2:$L$181,F$18) -> 0 | G22: =COUNTIFS(Incident_Data!$F$2:$F$181,$A22,Incident_Data!$L$2:$L$181,G$18) -> 0 | H22: =COUNTIFS(Incident_Data!$F$2:$F$181,$A22,Incident_Data!$L$2:$L$181,H$18) -> 0 | I22: =COUNTIFS(Incident_Data!$F$2:$F$181,$A22,Incident_Data!$L$2:$L$181,I$18) -> 4 | J22: =COUNTIFS(Incident_Data!$F$2:$F$181,$A22,Incident_Data!$L$2:$L$181,J$18) -> 0 | K22: =SUM(B22:J22) -> 25
A23: Legal | B23: =COUNTIFS(Incident_Data!$F$2:$F$181,$A23,Incident_Data!$L$2:$L$181,B$18) -> 10 | C23: =COUNTIFS(Incident_Data!$F$2:$F$181,$A23,Incident_Data!$L$2:$L$181,C$18) -> 0 | D23: =COUNTIFS(Incident_Data!$F$2:$F$181,$A23,Incident_Data!$L$2:$L$181,D$18) -> 6 | E23: =COUNTIFS(Incident_Data!$F$2:$F$181,$A23,Incident_Data!$L$2:$L$181,E$18) -> 0 | F23: =COUNTIFS(Incident_Data!$F$2:$F$181,$A23,Incident_Data!$L$2:$L$181,F$18) -> 0 | G23: =COUNTIFS(Incident_Data!$F$2:$F$181,$A23,Incident_Data!$L$2:$L$181,G$18) -> 10 | H23: =COUNTIFS(Incident_Data!$F$2:$F$181,$A23,Incident_Data!$L$2:$L$181,H$18) -> 0 | I23: =COUNTIFS(Incident_Data!$F$2:$F$181,$A23,Incident_Data!$L$2:$L$181,I$18) -> 0 | J23: =COUNTIFS(Incident_Data!$F$2:$F$181,$A23,Incident_Data!$L$2:$L$181,J$18) -> 0 | K23: =SUM(B23:J23) -> 26
A24: Cloud Operations | B24: =COUNTIFS(Incident_Data!$F$2:$F$181,$A24,Incident_Data!$L$2:$L$181,B$18) -> 3 | C24: =COUNTIFS(Incident_Data!$F$2:$F$181,$A24,Incident_Data!$L$2:$L$181,C$18) -> 0 | D24: =COUNTIFS(Incident_Data!$F$2:$F$181,$A24,Incident_Data!$L$2:$L$181,D$18) -> 4 | E24: =COUNTIFS(Incident_Data!$F$2:$F$181,$A24,Incident_Data!$L$2:$L$181,E$18) -> 0 | F24: =COUNTIFS(Incident_Data!$F$2:$F$181,$A24,Incident_Data!$L$2:$L$181,F$18) -> 3 | G24: =COUNTIFS(Incident_Data!$F$2:$F$181,$A24,Incident_Data!$L$2:$L$181,G$18) -> 0 | H24: =COUNTIFS(Incident_Data!$F$2:$F$181,$A24,Incident_Data!$L$2:$L$181,H$18) -> 0 | I24: =COUNTIFS(Incident_Data!$F$2:$F$181,$A24,Incident_Data!$L$2:$L$181,I$18) -> 0 | J24: =COUNTIFS(Incident_Data!$F$2:$F$181,$A24,Incident_Data!$L$2:$L$181,J$18) -> 0 | K24: =SUM(B24:J24) -> 10
A25: Student Services | B25: =COUNTIFS(Incident_Data!$F$2:$F$181,$A25,Incident_Data!$L$2:$L$181,B$18) -> 3 | C25: =COUNTIFS(Incident_Data!$F$2:$F$181,$A25,Incident_Data!$L$2:$L$181,C$18) -> 1 | D25: =COUNTIFS(Incident_Data!$F$2:$F$181,$A25,Incident_Data!$L$2:$L$181,D$18) -> 0 | E25: =COUNTIFS(Incident_Data!$F$2:$F$181,$A25,Incident_Data!$L$2:$L$181,E$18) -> 0 | F25: =COUNTIFS(Incident_Data!$F$2:$F$181,$A25,Incident_Data!$L$2:$L$181,F$18) -> 0 | G25: =COUNTIFS(Incident_Data!$F$2:$F$181,$A25,Incident_Data!$L$2:$L$181,G$18) -> 0 | H25: =COUNTIFS(Incident_Data!$F$2:$F$181,$A25,Incident_Data!$L$2:$L$181,H$18) -> 4 | I25: =COUNTIFS(Incident_Data!$F$2:$F$181,$A25,Incident_Data!$L$2:$L$181,I$18) -> 0 | J25: =COUNTIFS(Incident_Data!$F$2:$F$181,$A25,Incident_Data!$L$2:$L$181,J$18) -> 0 | K25: =SUM(B25:J25) -> 8
A26: Academic Services | B26: =COUNTIFS(Incident_Data!$F$2:$F$181,$A26,Incident_Data!$L$2:$L$181,B$18) -> 5 | C26: =COUNTIFS(Incident_Data!$F$2:$F$181,$A26,Incident_Data!$L$2:$L$181,C$18) -> 3 | D26: =COUNTIFS(Incident_Data!$F$2:$F$181,$A26,Incident_Data!$L$2:$L$181,D$18) -> 0 | E26: =COUNTIFS(Incident_Data!$F$2:$F$181,$A26,Incident_Data!$L$2:$L$181,E$18) -> 0 | F26: =COUNTIFS(Incident_Data!$F$2:$F$181,$A26,Incident_Data!$L$2:$L$181,F$18) -> 0 | G26: =COUNTIFS(Incident_Data!$F$2:$F$181,$A26,Incident_Data!$L$2:$L$181,G$18) -> 0 | H26: =COUNTIFS(Incident_Data!$F$2:$F$181,$A26,Incident_Data!$L$2:$L$181,H$18) -> 2 | I26: =COUNTIFS(Incident_Data!$F$2:$F$181,$A26,Incident_Data!$L$2:$L$181,I$18) -> 0 | J26: =COUNTIFS(Incident_Data!$F$2:$F$181,$A26,Incident_Data!$L$2:$L$181,J$18) -> 0 | K26: =SUM(B26:J26) -> 10
A27: Research | B27: =COUNTIFS(Incident_Data!$F$2:$F$181,$A27,Incident_Data!$L$2:$L$181,B$18) -> 3 | C27: =COUNTIFS(Incident_Data!$F$2:$F$181,$A27,Incident_Data!$L$2:$L$181,C$18) -> 0 | D27: =COUNTIFS(Incident_Data!$F$2:$F$181,$A27,Incident_Data!$L$2:$L$181,D$18) -> 2 | E27: =COUNTIFS(Incident_Data!$F$2:$F$181,$A27,Incident_Data!$L$2:$L$181,E$18) -> 0 | F27: =COUNTIFS(Incident_Data!$F$2:$F$181,$A27,Incident_Data!$L$2:$L$181,F$18) -> 0 | G27: =COUNTIFS(Incident_Data!$F$2:$F$181,$A27,Incident_Data!$L$2:$L$181,G$18) -> 0 | H27: =COUNTIFS(Incident_Data!$F$2:$F$181,$A27,Incident_Data!$L$2:$L$181,H$18) -> 0 | I27: =COUNTIFS(Incident_Data!$F$2:$F$181,$A27,Incident_Data!$L$2:$L$181,I$18) -> 0 | J27: =COUNTIFS(Incident_Data!$F$2:$F$181,$A27,Incident_Data!$L$2:$L$181,J$18) -> 1 | K27: =SUM(B27:J27) -> 6
A28: Total | B28: =SUM(B19:B27) -> 56 | C28: =SUM(C19:C27) -> 44 | D28: =SUM(D19:D27) -> 33 | E28: =SUM(E19:E27) -> 14 | F28: =SUM(F19:F27) -> 12 | G28: =SUM(G19:G27) -> 10 | H28: =SUM(H19:H27) -> 6 | I28: =SUM(I19:I27) -> 4 | ... K28: =SUM(K19:K27) -> 180
A30: 3. Incident_Type with any recorded exposure (Regulatory_Exposure <> None)
A31: Incident_Type | B31: Incidents | C31: With exposure | D31: % with exposure
A32: Malware | B32: =COUNTIF(Incident_Data!$C$2:$C$181,A32) -> 28 | C32: =COUNTIFS(Incident_Data!$C$2:$C$181,A32,Incident_Data!$L$2:$L$181,"<>None") -> 19 | D32: =C32/B32 -> 0.67857143
A33: Phishing | B33: =COUNTIF(Incident_Data!$C$2:$C$181,A33) -> 28 | C33: =COUNTIFS(Incident_Data!$C$2:$C$181,A33,Incident_Data!$L$2:$L$181,"<>None") -> 25 | D33: =C33/B33 -> 0.89285714
A34: Data Leak | B34: =COUNTIF(Incident_Data!$C$2:$C$181,A34) -> 27 | C34: =COUNTIFS(Incident_Data!$C$2:$C$181,A34,Incident_Data!$L$2:$L$181,"<>None") -> 21 | D34: =C34/B34 -> 0.77777778
A35: Unauthorized Access | B35: =COUNTIF(Incident_Data!$C$2:$C$181,A35) -> 24 | C35: =COUNTIFS(Incident_Data!$C$2:$C$181,A35,Incident_Data!$L$2:$L$181,"<>None") -> 15 | D35: =C35/B35 -> 0.625
A36: Misconfiguration | B36: =COUNTIF(Incident_Data!$C$2:$C$181,A36) -> 19 | C36: =COUNTIFS(Incident_Data!$C$2:$C$181,A36,Incident_Data!$L$2:$L$181,"<>None") -> 13 | D36: =C36/B36 -> 0.68421053
A37: DDoS | B37: =COUNTIF(Incident_Data!$C$2:$C$181,A37) -> 19 | C37: =COUNTIFS(Incident_Data!$C$2:$C$181,A37,Incident_Data!$L$2:$L$181,"<>None") -> 16 | D37: =C37/B37 -> 0.84210526
A38: Cloud Exposure | B38: =COUNTIF(Incident_Data!$C$2:$C$181,A38) -> 11 | C38: =COUNTIFS(Incident_Data!$C$2:$C$181,A38,Incident_Data!$L$2:$L$181,"<>None") -> 9 | D38: =C38/B38 -> 0.81818182
A39: Credential Theft | B39: =COUNTIF(Incident_Data!$C$2:$C$181,A39) -> 9 | C39: =COUNTIFS(Incident_Data!$C$2:$C$181,A39,Incident_Data!$L$2:$L$181,"<>None") -> 7 | D39: =C39/B39 -> 0.77777778
A40: Third-Party Breach | B40: =COUNTIF(Incident_Data!$C$2:$C$181,A40) -> 6 | C40: =COUNTIFS(Incident_Data!$C$2:$C$181,A40,Incident_Data!$L$2:$L$181,"<>None") -> 3 | D40: =C40/B40 -> 0.5
A41: Insider Threat | B41: =COUNTIF(Incident_Data!$C$2:$C$181,A41) -> 5 | C41: =COUNTIFS(Incident_Data!$C$2:$C$181,A41,Incident_Data!$L$2:$L$181,"<>None") -> 4 | D41: =C41/B41 -> 0.8
A42: Lost Device | B42: =COUNTIF(Incident_Data!$C$2:$C$181,A42) -> 3 | C42: =COUNTIFS(Incident_Data!$C$2:$C$181,A42,Incident_Data!$L$2:$L$181,"<>None") -> 3 | D42: =C42/B42 -> 1
A43: Policy Violation | B43: =COUNTIF(Incident_Data!$C$2:$C$181,A43) -> 1 | C43: =COUNTIFS(Incident_Data!$C$2:$C$181,A43,Incident_Data!$L$2:$L$181,"<>None") -> 1 | D43: =C43/B43 -> 1
...

Sheet Third_Party
A1: Part D2 - Third-party involvement
A2: Pattern analysis only: an association in a simulated dataset does not prove that third parties caused the difference.
A4: Measure | B4: Third party = Yes | C4: Third party = No | D4: Difference (Yes - No)
A5: Incidents | B5: =COUNTIF(Incident_Data!$N$2:$N$181,"Yes") -> 43 | C5: =COUNTIF(Incident_Data!$N$2:$N$181,"No") -> 137 | D5: =B5-C5 -> -94
A6: % of all incidents | B6: =B5/'Core Analysis'!$B$6 -> 0.23888889 | C6: =C5/'Core Analysis'!$B$6 -> 0.76111111 | D6: =B6-C6 -> -0.52222222
A7: Average Cost_Impact_USD | B7: =AVERAGEIF(Incident_Data!$N$2:$N$181,"Yes",Incident_Data!$I$2:$I$181) -> 73699.698 | C7: =AVERAGEIF(Incident_Data!$N$2:$N$181,"No",Incident_Data!$I$2:$I$181) -> 52002.445 | D7: =B7-C7 -> 21697.252
A8: Average cost excluding Incident_Type = Third-Party Breach | B8: =AVERAGEIFS(Incident_Data!$I$2:$I$181,Incident_Data!$N$2:$N$181,"Yes",Incident_Data!$C$2:$C$181,"<>Third-Party Breach") -> 70588.027 | C8: =AVERAGEIFS(Incident_Data!$I$2:$I$181,Incident_Data!$N$2:$N$181,"No",Incident_Data!$C$2:$C$181,"<>Third-Party Breach") -> 52002.445 | D8: =B8-C8 -> 18585.582
A9: Average Resolution_Time_Days | B9: =AVERAGEIF(Incident_Data!$N$2:$N$181,"Yes",Incident_Data!$H$2:$H$181) -> 12.744186 | C9: =AVERAGEIF(Incident_Data!$N$2:$N$181,"No",Incident_Data!$H$2:$H$181) -> 14.532847 | D9: =B9-C9 -> -1.7886607
A10: Critical incidents | B10: =COUNTIFS(Incident_Data!$N$2:$N$181,"Yes",Incident_Data!$D$2:$D$181,"Critical") -> 6 | C10: =COUNTIFS(Incident_Data!$N$2:$N$181,"No",Incident_Data!$D$2:$D$181,"Critical") -> 14 | D10: =B10-C10 -> -8
A11: % Critical | B11: =B10/B5 -> 0.13953488 | C11: =C10/C5 -> 0.10218978 | D11: =B11-C11 -> 0.037345103
A12: Critical + High incidents | B12: =COUNTIFS(Incident_Data!$N$2:$N$181,"Yes",Incident_Data!$D$2:$D$181,"Critical")+COUNTIFS(Incident_Data!$N$2:$N$181,"Yes",Incident_Data!$D$2:$D$181,"High") -> 18 | C12: =COUNTIFS(Incident_Data!$N$2:$N$181,"No",Incident_Data!$D$2:$D$181,"Critical")+COUNTIFS(Incident_Data!$N$2:$N$181,"No",Incident_Data!$D$2:$D$181,"High") -> 55 | D12: =B12-C12 -> -37
A13: % Critical + High | B13: =B12/B5 -> 0.41860465 | C13: =C12/C5 -> 0.40145985 | D13: =B13-C13 -> 0.017144797
A14: Escalation: Board / Executive | B14: =COUNTIFS(Incident_Data!$N$2:$N$181,"Yes",Incident_Data!$M$2:$M$181,"Board / Executive") -> 6 | C14: =COUNTIFS(Incident_Data!$N$2:$N$181,"No",Incident_Data!$M$2:$M$181,"Board / Executive") -> 14 | D14: =B14-C14 -> -8
A15: Escalation: Executive / CISO | B15: =COUNTIFS(Incident_Data!$N$2:$N$181,"Yes",Incident_Data!$M$2:$M$181,"Executive / CISO") -> 12 | C15: =COUNTIFS(Incident_Data!$N$2:$N$181,"No",Incident_Data!$M$2:$M$181,"Executive / CISO") -> 41 | D15: =B15-C15 -> -29
A16: Escalation: CISO / Department Head | B16: =COUNTIFS(Incident_Data!$N$2:$N$181,"Yes",Incident_Data!$M$2:$M$181,"CISO / Department Head") -> 19 | C16: =COUNTIFS(Incident_Data!$N$2:$N$181,"No",Incident_Data!$M$2:$M$181,"CISO / Department Head") -> 61 | D16: =B16-C16 -> -42
A17: Escalation: Operational | B17: =COUNTIFS(Incident_Data!$N$2:$N$181,"Yes",Incident_Data!$M$2:$M$181,"Operational") -> 6 | C17: =COUNTIFS(Incident_Data!$N$2:$N$181,"No",Incident_Data!$M$2:$M$181,"Operational") -> 21 | D17: =B17-C17 -> -15
A18: % escalated to Board / Executive | B18: =B14/B5 -> 0.13953488 | C18: =C14/C5 -> 0.10218978 | D18: =B18-C18 -> 0.037345103
A19: Breach rate (all incidents) | B19: =COUNTIFS(Incident_Data!$N$2:$N$181,"Yes",Incident_Data!$P$2:$P$181,"Yes")/B5 -> 0.25581395 | C19: =COUNTIFS(Incident_Data!$N$2:$N$181,"No",Incident_Data!$P$2:$P$181,"Yes")/C5 -> 0.31386861 | D19: =B19-C19 -> -0.05805466
A21: Indicative significance test on average cost (Welch's t-test, computed from the data)
A22: Variance, third party = Yes | B22: =(SUMPRODUCT((Incident_Data!$N$2:$N$181="Yes")*(Incident_Data!$I$2:$I$181-B7)^2)/(COUNTIF(Incident_Data!$N$2:$N$181,"Yes")-1)) -> 2.3190976e+09
A23: Variance, third party = No | B23: =(SUMPRODUCT((Incident_Data!$N$2:$N$181="No")*(Incident_Data!$I$2:$I$181-C7)^2)/(COUNTIF(Incident_Data!$N$2:$N$181,"No")-1)) -> 1.0984167e+09
A24: Welch t statistic | B24: =(B7-C7)/SQRT(B22/B5+B23/C5) -> 2.7566624
A25: Welch degrees of freedom (approx.) | B25: =(B22/B5+B23/C5)^2/((B22/B5)^2/(B5-1)+(B23/C5)^2/(C5-1)) -> 55.040044
A26: Two-tailed p-value (approx.) | B26: =TDIST(ABS(B24),ROUNDDOWN(B25,0),2) -> 0.0079073603
A29: Incident_Type x third-party involvement (context for the cost gap)
A30: Incident_Type | B30: Third party = Yes | C30: Third party = No | D30: % third party
A31: Malware | B31: =COUNTIFS(Incident_Data!$C$2:$C$181,A31,Incident_Data!$N$2:$N$181,"Yes") -> 3 | C31: =COUNTIFS(Incident_Data!$C$2:$C$181,A31,Incident_Data!$N$2:$N$181,"No") -> 25 | D31: =B31/(B31+C31) -> 0.10714286
A32: Phishing | B32: =COUNTIFS(Incident_Data!$C$2:$C$181,A32,Incident_Data!$N$2:$N$181,"Yes") -> 1 | C32: =COUNTIFS(Incident_Data!$C$2:$C$181,A32,Incident_Data!$N$2:$N$181,"No") -> 27 | D32: =B32/(B32+C32) -> 0.035714286
A33: Data Leak | B33: =COUNTIFS(Incident_Data!$C$2:$C$181,A33,Incident_Data!$N$2:$N$181,"Yes") -> 9 | C33: =COUNTIFS(Incident_Data!$C$2:$C$181,A33,Incident_Data!$N$2:$N$181,"No") -> 18 | D33: =B33/(B33+C33) -> 0.33333333
A34: Unauthorized Access | B34: =COUNTIFS(Incident_Data!$C$2:$C$181,A34,Incident_Data!$N$2:$N$181,"Yes") -> 1 | C34: =COUNTIFS(Incident_Data!$C$2:$C$181,A34,Incident_Data!$N$2:$N$181,"No") -> 23 | D34: =B34/(B34+C34) -> 0.041666667
A35: Misconfiguration | B35: =COUNTIFS(Incident_Data!$C$2:$C$181,A35,Incident_Data!$N$2:$N$181,"Yes") -> 4 | C35: =COUNTIFS(Incident_Data!$C$2:$C$181,A35,Incident_Data!$N$2:$N$181,"No") -> 15 | D35: =B35/(B35+C35) -> 0.21052632
A36: DDoS | B36: =COUNTIFS(Incident_Data!$C$2:$C$181,A36,Incident_Data!$N$2:$N$181,"Yes") -> 7 | C36: =COUNTIFS(Incident_Data!$C$2:$C$181,A36,Incident_Data!$N$2:$N$181,"No") -> 12 | D36: =B36/(B36+C36) -> 0.36842105
A37: Cloud Exposure | B37: =COUNTIFS(Incident_Data!$C$2:$C$181,A37,Incident_Data!$N$2:$N$181,"Yes") -> 11 | C37: =COUNTIFS(Incident_Data!$C$2:$C$181,A37,Incident_Data!$N$2:$N$181,"No") -> 0 | D37: =B37/(B37+C37) -> 1
A38: Credential Theft | B38: =COUNTIFS(Incident_Data!$C$2:$C$181,A38,Incident_Data!$N$2:$N$181,"Yes") -> 1 | C38: =COUNTIFS(Incident_Data!$C$2:$C$181,A38,Incident_Data!$N$2:$N$181,"No") -> 8 | D38: =B38/(B38+C38) -> 0.11111111
A39: Third-Party Breach | B39: =COUNTIFS(Incident_Data!$C$2:$C$181,A39,Incident_Data!$N$2:$N$181,"Yes") -> 6 | C39: =COUNTIFS(Incident_Data!$C$2:$C$181,A39,Incident_Data!$N$2:$N$181,"No") -> 0 | D39: =B39/(B39+C39) -> 1
A40: Insider Threat | B40: =COUNTIFS(Incident_Data!$C$2:$C$181,A40,Incident_Data!$N$2:$N$181,"Yes") -> 0 | C40: =COUNTIFS(Incident_Data!$C$2:$C$181,A40,Incident_Data!$N$2:$N$181,"No") -> 5 | D40: =B40/(B40+C40) -> 0
A41: Lost Device | B41: =COUNTIFS(Incident_Data!$C$2:$C$181,A41,Incident_Data!$N$2:$N$181,"Yes") -> 0 | C41: =COUNTIFS(Incident_Data!$C$2:$C$181,A41,Incident_Data!$N$2:$N$181,"No") -> 3 | D41: =B41/(B41+C41) -> 0
A42: Policy Violation | B42: =COUNTIFS(Incident_Data!$C$2:$C$181,A42,Incident_Data!$N$2:$N$181,"Yes") -> 0 | C42: =COUNTIFS(Incident_Data!$C$2:$C$181,A42,Incident_Data!$N$2:$N$181,"No") -> 1 | D42: =B42/(B42+C42) -> 0
A43: Total | B43: =SUM(B31:B42) -> 43 | C43: =SUM(C31:C42) -> 137 | D43: =B43/(B43+C43) -> 0.23888889

Sheet Control_Domain
A1: Part D2 - Control_Domain analysis
A2: Sorted by incident count. Breach rate (all) divides by every incident; Closed-only divides by incidents with a final SLA outcome.
A4: Control_Domain summary
A5: Control_Domain | B5: Incidents | C5: % of incidents | D5: Total cost (USD) | E5: Average cost (USD) | F5: SLA Yes | G5: SLA No | H5: Breach rate (all incidents) | I5: Breach rate (Closed only) | J5: Avg Resolution_Time_Days
A6: Identity & Access Management | B6: =COUNTIF(Incident_Data!$K$2:$K$181,A6) -> 33 | C6: =B6/'Core Analysis'!$B$6 -> 0.18333333 | D6: =SUMIF(Incident_Data!$K$2:$K$181,A6,Incident_Data!$I$2:$I$181) -> 1932469 | E6: =AVERAGEIF(Incident_Data!$K$2:$K$181,A6,Incident_Data!$I$2:$I$181) -> 58559.667 | F6: =COUNTIFS(Incident_Data!$K$2:$K$181,A6,Incident_Data!$P$2:$P$181,"Yes") -> 7 | G6: =COUNTIFS(Incident_Data!$K$2:$K$181,A6,Incident_Data!$P$2:$P$181,"No") -> 14 | H6: =F6/B6 -> 0.21212121 | I6: =IF(F6+G6=0,0,F6/(F6+G6)) -> 0.33333333 | J6: =AVERAGEIF(Incident_Data!$K$2:$K$181,A6,Incident_Data!$H$2:$H$181) -> 14.212121
A7: Endpoint Security | B7: =COUNTIF(Incident_Data!$K$2:$K$181,A7) -> 28 | C7: =B7/'Core Analysis'!$B$6 -> 0.15555556 | D7: =SUMIF(Incident_Data!$K$2:$K$181,A7,Incident_Data!$I$2:$I$181) -> 1528133 | E7: =AVERAGEIF(Incident_Data!$K$2:$K$181,A7,Incident_Data!$I$2:$I$181) -> 54576.179 | F7: =COUNTIFS(Incident_Data!$K$2:$K$181,A7,Incident_Data!$P$2:$P$181,"Yes") -> 9 | G7: =COUNTIFS(Incident_Data!$K$2:$K$181,A7,Incident_Data!$P$2:$P$181,"No") -> 8 | H7: =F7/B7 -> 0.32142857 | I7: =IF(F7+G7=0,0,F7/(F7+G7)) -> 0.52941176 | J7: =AVERAGEIF(Incident_Data!$K$2:$K$181,A7,Incident_Data!$H$2:$H$181) -> 16.071429
A8: Security Awareness | B8: =COUNTIF(Incident_Data!$K$2:$K$181,A8) -> 28 | C8: =B8/'Core Analysis'!$B$6 -> 0.15555556 | D8: =SUMIF(Incident_Data!$K$2:$K$181,A8,Incident_Data!$I$2:$I$181) -> 1065731 | E8: =AVERAGEIF(Incident_Data!$K$2:$K$181,A8,Incident_Data!$I$2:$I$181) -> 38061.821 | F8: =COUNTIFS(Incident_Data!$K$2:$K$181,A8,Incident_Data!$P$2:$P$181,"Yes") -> 9 | G8: =COUNTIFS(Incident_Data!$K$2:$K$181,A8,Incident_Data!$P$2:$P$181,"No") -> 10 | H8: =F8/B8 -> 0.32142857 | I8: =IF(F8+G8=0,0,F8/(F8+G8)) -> 0.47368421 | J8: =AVERAGEIF(Incident_Data!$K$2:$K$181,A8,Incident_Data!$H$2:$H$181) -> 12.642857
A9: Data Protection | B9: =COUNTIF(Incident_Data!$K$2:$K$181,A9) -> 27 | C9: =B9/'Core Analysis'!$B$6 -> 0.15 | D9: =SUMIF(Incident_Data!$K$2:$K$181,A9,Incident_Data!$I$2:$I$181) -> 1452637 | E9: =AVERAGEIF(Incident_Data!$K$2:$K$181,A9,Incident_Data!$I$2:$I$181) -> 53801.37 | F9: =COUNTIFS(Incident_Data!$K$2:$K$181,A9,Incident_Data!$P$2:$P$181,"Yes") -> 9 | G9: =COUNTIFS(Incident_Data!$K$2:$K$181,A9,Incident_Data!$P$2:$P$181,"No") -> 7 | H9: =F9/B9 -> 0.33333333 | I9: =IF(F9+G9=0,0,F9/(F9+G9)) -> 0.5625 | J9: =AVERAGEIF(Incident_Data!$K$2:$K$181,A9,Incident_Data!$H$2:$H$181) -> 14.740741
A10: Configuration Management | B10: =COUNTIF(Incident_Data!$K$2:$K$181,A10) -> 19 | C10: =B10/'Core Analysis'!$B$6 -> 0.10555556 | D10: =SUMIF(Incident_Data!$K$2:$K$181,A10,Incident_Data!$I$2:$I$181) -> 880043 | E10: =AVERAGEIF(Incident_Data!$K$2:$K$181,A10,Incident_Data!$I$2:$I$181) -> 46318.053 | F10: =COUNTIFS(Incident_Data!$K$2:$K$181,A10,Incident_Data!$P$2:$P$181,"Yes") -> 9 | G10: =COUNTIFS(Incident_Data!$K$2:$K$181,A10,Incident_Data!$P$2:$P$181,"No") -> 4 | H10: =F10/B10 -> 0.47368421 | I10: =IF(F10+G10=0,0,F10/(F10+G10)) -> 0.69230769 | J10: =AVERAGEIF(Incident_Data!$K$2:$K$181,A10,Incident_Data!$H$2:$H$181) -> 16.368421
A11: Network Resilience | B11: =COUNTIF(Incident_Data!$K$2:$K$181,A11) -> 19 | C11: =B11/'Core Analysis'!$B$6 -> 0.10555556 | D11: =SUMIF(Incident_Data!$K$2:$K$181,A11,Incident_Data!$I$2:$I$181) -> 1061329 | E11: =AVERAGEIF(Incident_Data!$K$2:$K$181,A11,Incident_Data!$I$2:$I$181) -> 55859.421 | F11: =COUNTIFS(Incident_Data!$K$2:$K$181,A11,Incident_Data!$P$2:$P$181,"Yes") -> 3 | G11: =COUNTIFS(Incident_Data!$K$2:$K$181,A11,Incident_Data!$P$2:$P$181,"No") -> 6 | H11: =F11/B11 -> 0.15789474 | I11: =IF(F11+G11=0,0,F11/(F11+G11)) -> 0.33333333 | J11: =AVERAGEIF(Incident_Data!$K$2:$K$181,A11,Incident_Data!$H$2:$H$181) -> 14.052632
A12: Cloud Security | B12: =COUNTIF(Incident_Data!$K$2:$K$181,A12) -> 11 | C12: =B12/'Core Analysis'!$B$6 -> 0.061111111 | D12: =SUMIF(Incident_Data!$K$2:$K$181,A12,Incident_Data!$I$2:$I$181) -> 1043310 | E12: =AVERAGEIF(Incident_Data!$K$2:$K$181,A12,Incident_Data!$I$2:$I$181) -> 94846.364 | F12: =COUNTIFS(Incident_Data!$K$2:$K$181,A12,Incident_Data!$P$2:$P$181,"Yes") -> 5 | G12: =COUNTIFS(Incident_Data!$K$2:$K$181,A12,Incident_Data!$P$2:$P$181,"No") -> 5 | H12: =F12/B12 -> 0.45454545 | I12: =IF(F12+G12=0,0,F12/(F12+G12)) -> 0.5 | J12: =AVERAGEIF(Incident_Data!$K$2:$K$181,A12,Incident_Data!$H$2:$H$181) -> 13.454545
A13: Third-Party Risk | B13: =COUNTIF(Incident_Data!$K$2:$K$181,A13) -> 6 | C13: =B13/'Core Analysis'!$B$6 -> 0.033333333 | D13: =SUMIF(Incident_Data!$K$2:$K$181,A13,Incident_Data!$I$2:$I$181) -> 557330 | E13: =AVERAGEIF(Incident_Data!$K$2:$K$181,A13,Incident_Data!$I$2:$I$181) -> 92888.333 | F13: =COUNTIFS(Incident_Data!$K$2:$K$181,A13,Incident_Data!$P$2:$P$181,"Yes") -> 1 | G13: =COUNTIFS(Incident_Data!$K$2:$K$181,A13,Incident_Data!$P$2:$P$181,"No") -> 5 | H13: =F13/B13 -> 0.16666667 | I13: =IF(F13+G13=0,0,F13/(F13+G13)) -> 0.16666667 | J13: =AVERAGEIF(Incident_Data!$K$2:$K$181,A13,Incident_Data!$H$2:$H$181) -> 12.5
A14: Privileged Access & Monitoring | B14: =COUNTIF(Incident_Data!$K$2:$K$181,A14) -> 5 | C14: =B14/'Core Analysis'!$B$6 -> 0.027777778 | D14: =SUMIF(Incident_Data!$K$2:$K$181,A14,Incident_Data!$I$2:$I$181) -> 692530 | E14: =AVERAGEIF(Incident_Data!$K$2:$K$181,A14,Incident_Data!$I$2:$I$181) -> 138506 | F14: =COUNTIFS(Incident_Data!$K$2:$K$181,A14,Incident_Data!$P$2:$P$181,"Yes") -> 1 | G14: =COUNTIFS(Incident_Data!$K$2:$K$181,A14,Incident_Data!$P$2:$P$181,"No") -> 2 | H14: =F14/B14 -> 0.2 | I14: =IF(F14+G14=0,0,F14/(F14+G14)) -> 0.33333333 | J14: =AVERAGEIF(Incident_Data!$K$2:$K$181,A14,Incident_Data!$H$2:$H$181) -> 5.2
A15: Asset & Endpoint Security | B15: =COUNTIF(Incident_Data!$K$2:$K$181,A15) -> 3 | C15: =B15/'Core Analysis'!$B$6 -> 0.016666667 | D15: =SUMIF(Incident_Data!$K$2:$K$181,A15,Incident_Data!$I$2:$I$181) -> 62510 | E15: =AVERAGEIF(Incident_Data!$K$2:$K$181,A15,Incident_Data!$I$2:$I$181) -> 20836.667 | F15: =COUNTIFS(Incident_Data!$K$2:$K$181,A15,Incident_Data!$P$2:$P$181,"Yes") -> 0 | G15: =COUNTIFS(Incident_Data!$K$2:$K$181,A15,Incident_Data!$P$2:$P$181,"No") -> 2 | H15: =F15/B15 -> 0 | I15: =IF(F15+G15=0,0,F15/(F15+G15)) -> 0 | J15: =AVERAGEIF(Incident_Data!$K$2:$K$181,A15,Incident_Data!$H$2:$H$181) -> 10.666667
A16: Policy Compliance | B16: =COUNTIF(Incident_Data!$K$2:$K$181,A16) -> 1 | C16: =B16/'Core Analysis'!$B$6 -> 0.0055555556 | D16: =SUMIF(Incident_Data!$K$2:$K$181,A16,Incident_Data!$I$2:$I$181) -> 17400 | E16: =AVERAGEIF(Incident_Data!$K$2:$K$181,A16,Incident_Data!$I$2:$I$181) -> 17400 | F16: =COUNTIFS(Incident_Data!$K$2:$K$181,A16,Incident_Data!$P$2:$P$181,"Yes") -> 1 | G16: =COUNTIFS(Incident_Data!$K$2:$K$181,A16,Incident_Data!$P$2:$P$181,"No") -> 0 | H16: =F16/B16 -> 1 | I16: =IF(F16+G16=0,0,F16/(F16+G16)) -> 1 | J16: =AVERAGEIF(Incident_Data!$K$2:$K$181,A16,Incident_Data!$H$2:$H$181) -> 9
A17: Total | B17: =SUM(B6:B16) -> 180 | C17: =SUM(C6:C16) -> 1 | D17: =SUM(D6:D16) -> 10293422 | E17: =D17/B17 -> 57185.678 | F17: =SUM(F6:F16) -> 54 | G17: =SUM(G6:G16) -> 63 | H17: =F17/B17 -> 0.3 | I17: =F17/(F17+G17) -> 0.46153846 | J17: =AVERAGE(Incident_Data!$H$2:$H$181) -> 14.105556
A19: Identity & Access Management - Root_Cause breakdown
A20: Root_Cause | B20: Incidents | C20: % of IAM incidents
A21: Excessive privileges | B21: =COUNTIFS(Incident_Data!$K$2:$K$181,"Identity & Access Management",Incident_Data!$J$2:$J$181,A21) -> 9 | C21: =B21/$B$6 -> 0.27272727
A22: Compromised credentials | B22: =COUNTIFS(Incident_Data!$K$2:$K$181,"Identity & Access Management",Incident_Data!$J$2:$J$181,A22) -> 8 | C22: =B22/$B$6 -> 0.24242424
A23: Dormant account misuse | B23: =COUNTIFS(Incident_Data!$K$2:$K$181,"Identity & Access Management",Incident_Data!$J$2:$J$181,A23) -> 7 | C23: =B23/$B$6 -> 0.21212121
A24: Phishing | B24: =COUNTIFS(Incident_Data!$K$2:$K$181,"Identity & Access Management",Incident_Data!$J$2:$J$181,A24) -> 5 | C24: =B24/$B$6 -> 0.15151515
A25: Password reuse | B25: =COUNTIFS(Incident_Data!$K$2:$K$181,"Identity & Access Management",Incident_Data!$J$2:$J$181,A25) -> 3 | C25: =B25/$B$6 -> 0.090909091
A26: MFA fatigue attack | B26: =COUNTIFS(Incident_Data!$K$2:$K$181,"Identity & Access Management",Incident_Data!$J$2:$J$181,A26) -> 1 | C26: =B26/$B$6 -> 0.03030303
A27: Total | B27: =SUM(B21:B26) -> 33 | C27: =SUM(C21:C26) -> 1

Sheet CISO_Board_Insights
A1: Part D3 - Three CISO / Board insights
A2: Supporting-data column is formula-driven from the analysis sheets. Order and targets match the written report.
A4: # | B4: Finding | C4: Supporting data (live) | D4: Governance significance | E4: Accountable / Responsible roles | F4: Recommended action | G4: Owner | H4: Success indicator
A5: 1 | B5: Critical and High severity incidents frequently miss their SLA targets. | C5: ="Critical: "&SLA_Analysis!D6&" of "&SLA_Analysis!E6&" breached ("&TEXT(SLA_Analysis!F6,"0.00%")&"). High: "&SLA_Analysis!D7&" of "&SLA_Analysis!E7&" ("&TEXT(SLA_Analysis!F7,"0.00%")&"). Critical avg resolution "&TEXT('Core Analysis'!C54,"0.00")&" days vs a "&'Core Analysis'!E54&"-day SLA. See Chart 6." -> Critical: 12 of 20 breached (60.00%). High: 25 of 53 (47.17%). Critical avg resolution 9.80 days vs a 3-day SLA. See Chart 6. | D5: Serious incidents stay open longer than the agreed target, extending exposure to risk and delaying Board and regulator visibility. | E5: Accountable: CISO and CRO. Responsible: IT Security and DevOps (highest breach rates among the larger teams). | F5: Review SLA targets and the escalation process for Critical and High incidents; use a dashboard that automatically escalates cases approaching their SLA limit. | G5: CISO (with CRO) | H5: Reduce the Critical SLA breach rate from 60.00% to below 30% within two reporting cycles.
A6: 2 | B6: Insider Threat is infrequent but has the highest average cost. | C6: ='Core Analysis'!B33&" incidents ("&TEXT('Core Analysis'!B33/'Core Analysis'!B6,"0.00%")&" of all) with average cost "&TEXT('Core Analysis'!C33,"$#,##0")&"; total "&TEXT('Core Analysis'!D33,"$#,##0")&". See Chart 4." -> 5 incidents (2.78% of all) with average cost $138,506; total $692,530. See Chart 4. | D6: Frequency alone should not drive priority. Insider cases cut across HR, Legal, IT and Security and link to the delayed-access-removal scenario in Part A5. | E6: Accountable: CISO and HR. Legal consulted on employment and privacy matters. IT responsible for access removal. | F6: Strengthen privileged access reviews, add monitoring of unusual user activity, and connect the HR termination process to IAM so access is removed quickly. | G6: CISO with HR | H6: 100% access removal within two hours of termination; reduce average Insider Threat cost by 30% within 12 months.
A7: 3 | B7: Identity and Access Management has the most incidents of any control domain. | C7: ="IAM: "&Control_Domain!B6&" incidents ("&TEXT(Control_Domain!C6,"0.0%")&" of all). Top root causes: "&Control_Domain!A21&" ("&Control_Domain!B21&"), "&Control_Domain!A22&" ("&Control_Domain!B22&"), "&Control_Domain!A23&" ("&Control_Domain!B23&"). See Chart 7." -> IAM: 33 incidents (18.3% of all). Top root causes: Excessive privileges (9), Compromised credentials (8), Dormant account misuse (7). See Chart 7. | D7: Weak access control affects every department and links to unauthorised access, data exposure and privileged-account misuse. Change Healthcare (Part C) shows the same theme: the first compromised server lacked MFA. | E7: Accountable: CISO. Responsible: IT and IAM team. HR involved through joiner-mover-leaver processes. | F7: Implement or strengthen Privileged Access Management, enforce phishing-resistant MFA for privileged accounts and sensitive help-desk actions, and run quarterly privileged-access reviews. | G7: CISO with IT and HR | H7: Reduce IAM incidents by 40% in nine months; 100% MFA coverage for privileged accounts; at least 95% on-time manager attestation in quarterly reviews.

Sheet Charts
A1: Part D charts (native Excel charts linked to the analysis sheets)
